2025-01-28 21:20:15,664 - INFO - Found 2 keywords to process
2025-01-28 21:20:15,664 - INFO - Keywords: ['Type_1_Diabetes', 'Type_2_Diabetes']
2025-01-28 21:20:15,664 - INFO - Resuming from checkpoint: i=0, j=0
2025-01-28 21:20:15,666 - INFO - 
Processing trait (1/2): Type_1_Diabetes
2025-01-28 21:20:15,666 - INFO - Search query: (30:10000[Number of Samples]) AND ("Homo sapiens"[Organism]) AND (2010:2025[Publication Date]) AND (Type_1_Diabetes) AND ("expression profiling by array"[DataSet Type] OR "expression profiling by high throughput sequencing"[DataSet Type] OR "genome variation profiling by high throughput sequencing"[DataSet Type] OR "genome variation profiling by snp array"[DataSet Type] OR "snp genotyping by snp array"[DataSet Type] OR "third party reanalysis"[DataSet Type])
2025-01-28 21:20:16,335 - INFO - Total results for query: 101
2025-01-28 21:20:16,335 - INFO - Fetching batch 1 of 2 (size: 100)
2025-01-28 21:20:16,603 - INFO - Successfully retrieved 100 IDs in batch 1
2025-01-28 21:20:17,103 - INFO - Fetching batch 2 of 2 (size: 1)
2025-01-28 21:20:17,900 - INFO - Successfully retrieved 1 IDs in batch 2
2025-01-28 21:20:17,900 - INFO - Found 101 datasets for: Type_1_Diabetes
2025-01-28 21:23:27,094 - ERROR - Error processing dataset 200216678: Remote end closed connection without response
Traceback (most recent call last):
  File "/home/techt/Desktop/GenoAgent/download/download_GEO_data.py", line 228, in get_GEO_series_access
    dataset_handle = Entrez.esummary(db="gds", id=dataset_id)
  File "/home/techt/anaconda3/envs/agent/lib/python3.10/site-packages/Bio/Entrez/__init__.py", line 345, in esummary
    return _open(request)
  File "/home/techt/anaconda3/envs/agent/lib/python3.10/site-packages/Bio/Entrez/__init__.py", line 634, in _open
    handle = urlopen(request)
  File "/home/techt/anaconda3/envs/agent/lib/python3.10/urllib/request.py", line 216, in urlopen
    return opener.open(url, data, timeout)
  File "/home/techt/anaconda3/envs/agent/lib/python3.10/urllib/request.py", line 519, in open
    response = self._open(req, data)
  File "/home/techt/anaconda3/envs/agent/lib/python3.10/urllib/request.py", line 536, in _open
    result = self._call_chain(self.handle_open, protocol, protocol +
  File "/home/techt/anaconda3/envs/agent/lib/python3.10/urllib/request.py", line 496, in _call_chain
    result = func(*args)
  File "/home/techt/anaconda3/envs/agent/lib/python3.10/urllib/request.py", line 1391, in https_open
    return self.do_open(http.client.HTTPSConnection, req,
  File "/home/techt/anaconda3/envs/agent/lib/python3.10/urllib/request.py", line 1352, in do_open
    r = h.getresponse()
  File "/home/techt/anaconda3/envs/agent/lib/python3.10/http/client.py", line 1375, in getresponse
    response.begin()
  File "/home/techt/anaconda3/envs/agent/lib/python3.10/http/client.py", line 318, in begin
    version, status, reason = self._read_status()
  File "/home/techt/anaconda3/envs/agent/lib/python3.10/http/client.py", line 287, in _read_status
    raise RemoteDisconnected("Remote end closed connection without"
http.client.RemoteDisconnected: Remote end closed connection without response

2025-01-28 21:23:48,069 - ERROR - Error processing dataset 200225336: Remote end closed connection without response
Traceback (most recent call last):
  File "/home/techt/Desktop/GenoAgent/download/download_GEO_data.py", line 228, in get_GEO_series_access
    dataset_handle = Entrez.esummary(db="gds", id=dataset_id)
  File "/home/techt/anaconda3/envs/agent/lib/python3.10/site-packages/Bio/Entrez/__init__.py", line 345, in esummary
    return _open(request)
  File "/home/techt/anaconda3/envs/agent/lib/python3.10/site-packages/Bio/Entrez/__init__.py", line 634, in _open
    handle = urlopen(request)
  File "/home/techt/anaconda3/envs/agent/lib/python3.10/urllib/request.py", line 216, in urlopen
    return opener.open(url, data, timeout)
  File "/home/techt/anaconda3/envs/agent/lib/python3.10/urllib/request.py", line 519, in open
    response = self._open(req, data)
  File "/home/techt/anaconda3/envs/agent/lib/python3.10/urllib/request.py", line 536, in _open
    result = self._call_chain(self.handle_open, protocol, protocol +
  File "/home/techt/anaconda3/envs/agent/lib/python3.10/urllib/request.py", line 496, in _call_chain
    result = func(*args)
  File "/home/techt/anaconda3/envs/agent/lib/python3.10/urllib/request.py", line 1391, in https_open
    return self.do_open(http.client.HTTPSConnection, req,
  File "/home/techt/anaconda3/envs/agent/lib/python3.10/urllib/request.py", line 1352, in do_open
    r = h.getresponse()
  File "/home/techt/anaconda3/envs/agent/lib/python3.10/http/client.py", line 1375, in getresponse
    response.begin()
  File "/home/techt/anaconda3/envs/agent/lib/python3.10/http/client.py", line 318, in begin
    version, status, reason = self._read_status()
  File "/home/techt/anaconda3/envs/agent/lib/python3.10/http/client.py", line 287, in _read_status
    raise RemoteDisconnected("Remote end closed connection without"
http.client.RemoteDisconnected: Remote end closed connection without response

2025-01-28 21:24:08,441 - ERROR - Error processing dataset 200221787: Remote end closed connection without response
Traceback (most recent call last):
  File "/home/techt/Desktop/GenoAgent/download/download_GEO_data.py", line 228, in get_GEO_series_access
    dataset_handle = Entrez.esummary(db="gds", id=dataset_id)
  File "/home/techt/anaconda3/envs/agent/lib/python3.10/site-packages/Bio/Entrez/__init__.py", line 345, in esummary
    return _open(request)
  File "/home/techt/anaconda3/envs/agent/lib/python3.10/site-packages/Bio/Entrez/__init__.py", line 634, in _open
    handle = urlopen(request)
  File "/home/techt/anaconda3/envs/agent/lib/python3.10/urllib/request.py", line 216, in urlopen
    return opener.open(url, data, timeout)
  File "/home/techt/anaconda3/envs/agent/lib/python3.10/urllib/request.py", line 519, in open
    response = self._open(req, data)
  File "/home/techt/anaconda3/envs/agent/lib/python3.10/urllib/request.py", line 536, in _open
    result = self._call_chain(self.handle_open, protocol, protocol +
  File "/home/techt/anaconda3/envs/agent/lib/python3.10/urllib/request.py", line 496, in _call_chain
    result = func(*args)
  File "/home/techt/anaconda3/envs/agent/lib/python3.10/urllib/request.py", line 1391, in https_open
    return self.do_open(http.client.HTTPSConnection, req,
  File "/home/techt/anaconda3/envs/agent/lib/python3.10/urllib/request.py", line 1352, in do_open
    r = h.getresponse()
  File "/home/techt/anaconda3/envs/agent/lib/python3.10/http/client.py", line 1375, in getresponse
    response.begin()
  File "/home/techt/anaconda3/envs/agent/lib/python3.10/http/client.py", line 318, in begin
    version, status, reason = self._read_status()
  File "/home/techt/anaconda3/envs/agent/lib/python3.10/http/client.py", line 287, in _read_status
    raise RemoteDisconnected("Remote end closed connection without"
http.client.RemoteDisconnected: Remote end closed connection without response

2025-01-28 21:24:29,824 - ERROR - Error processing dataset 200176171: Remote end closed connection without response
Traceback (most recent call last):
  File "/home/techt/Desktop/GenoAgent/download/download_GEO_data.py", line 228, in get_GEO_series_access
    dataset_handle = Entrez.esummary(db="gds", id=dataset_id)
  File "/home/techt/anaconda3/envs/agent/lib/python3.10/site-packages/Bio/Entrez/__init__.py", line 345, in esummary
    return _open(request)
  File "/home/techt/anaconda3/envs/agent/lib/python3.10/site-packages/Bio/Entrez/__init__.py", line 634, in _open
    handle = urlopen(request)
  File "/home/techt/anaconda3/envs/agent/lib/python3.10/urllib/request.py", line 216, in urlopen
    return opener.open(url, data, timeout)
  File "/home/techt/anaconda3/envs/agent/lib/python3.10/urllib/request.py", line 519, in open
    response = self._open(req, data)
  File "/home/techt/anaconda3/envs/agent/lib/python3.10/urllib/request.py", line 536, in _open
    result = self._call_chain(self.handle_open, protocol, protocol +
  File "/home/techt/anaconda3/envs/agent/lib/python3.10/urllib/request.py", line 496, in _call_chain
    result = func(*args)
  File "/home/techt/anaconda3/envs/agent/lib/python3.10/urllib/request.py", line 1391, in https_open
    return self.do_open(http.client.HTTPSConnection, req,
  File "/home/techt/anaconda3/envs/agent/lib/python3.10/urllib/request.py", line 1352, in do_open
    r = h.getresponse()
  File "/home/techt/anaconda3/envs/agent/lib/python3.10/http/client.py", line 1375, in getresponse
    response.begin()
  File "/home/techt/anaconda3/envs/agent/lib/python3.10/http/client.py", line 318, in begin
    version, status, reason = self._read_status()
  File "/home/techt/anaconda3/envs/agent/lib/python3.10/http/client.py", line 287, in _read_status
    raise RemoteDisconnected("Remote end closed connection without"
http.client.RemoteDisconnected: Remote end closed connection without response

